<?xml version="1.0" ?>
<!-- Generated using onshape-to-robot -->
<!-- Onshape https://cad.onshape.com/documents/865be092c66c9f7e37910352/w/5e74383f4d70a831a9754b12/e/6a9eb92becca39ddc7a0abc7 -->
<mujoco model="leg">
  <compiler angle="radian" meshdir="assets" autolimits="true"/>
  <default>
    <default class="leg">
      <joint frictionloss="0.1" armature="0.005"/>
      <position kp="50" dampratio="1"/>
      <default class="visual">
        <geom type="mesh" contype="0" conaffinity="0" group="2"/>
      </default>
      <default class="collision">
        <geom group="3"/>
      </default>
    </default>
  </default>
  <worldbody>
    <!-- Link weight -->
    <body name="weight" pos="0 0 0" quat="1 0 0 0" childclass="leg">
      <freejoint name="weight_freejoint"/>
      <inertial pos="0.100285 0.0083812 0.00128736" mass="25.5196" fullinertia="0.0146098 0.156525 0.152962 -0.00010012 -2.68236e-05 -9.24838e-05"/>
      <!-- Part rs04 -->
      <geom type="mesh" class="visual" pos="9.71445e-17 -0.0272 -4.16334e-17" quat="0 0 -0.707107 0.707107" mesh="rs04" material="rs04_material"/>
      <geom type="mesh" class="collision" pos="9.71445e-17 -0.0272 -4.16334e-17" quat="0 0 -0.707107 0.707107" mesh="rs04" material="rs04_material"/>
      <!-- Part rs04_2 -->
      <geom type="mesh" class="visual" pos="0.2 -0.0272 -4.16334e-17" quat="4.81603e-24 0 0.707107 -0.707107" mesh="rs04" material="rs04_material"/>
      <geom type="mesh" class="collision" pos="0.2 -0.0272 -4.16334e-17" quat="4.81603e-24 0 0.707107 -0.707107" mesh="rs04" material="rs04_material"/>
      <!-- Part weight -->
      <geom type="mesh" class="visual" pos="0.100389 0.025 0.00139878" quat="0.707107 0.707107 -0 -0" mesh="weight" material="weight_material"/>
      <geom type="mesh" class="collision" pos="0.100389 0.025 0.00139878" quat="0.707107 0.707107 -0 -0" mesh="weight" material="weight_material"/>
      <!-- IMU reference on the base weight -->
      <site name="imu_weight" pos="0 0 0" quat="1 0 0 0" size="0.01" rgba="0 0 1 0.3"/>
      <!-- Link hip -->
      <body name="hip" pos="-3.1572e-15 -0.0527 -2.05521e-15" quat="0 0 0.707107 0.707107">
        <!-- Joint from weight to hip -->
        <joint axis="0 0 1" name="hip-sway" type="hinge"/>
        <inertial pos="7.23173e-10 4.11021e-08 -0.0674747" mass="3.29742" fullinertia="0.00651198 0.0147053 0.0142296 7.75592e-05 -4.32513e-10 -6.63111e-09"/>
        <!-- Part hip -->
        <geom type="mesh" class="visual" pos="-0.1305 0.2067 -0.005" quat="0.5 -0.5 0.5 0.5" mesh="hip" material="hip_material"/>
        <geom type="mesh" class="collision" pos="-0.1305 0.2067 -0.005" quat="0.5 -0.5 0.5 0.5" mesh="hip" material="hip_material"/>
        <!-- Part rs04_3 -->
        <geom type="mesh" class="visual" pos="-0.05675 1.23491e-16 -0.07" quat="0.5 0.5 0.5 0.5" mesh="rs04" material="rs04_material"/>
        <geom type="mesh" class="collision" pos="-0.05675 1.23491e-16 -0.07" quat="0.5 0.5 0.5 0.5" mesh="rs04" material="rs04_material"/>
        <!-- Part rs04_4 -->
        <geom type="mesh" class="visual" pos="0.05675 8.86335e-17 -0.07" quat="0.5 0.5 -0.5 -0.5" mesh="rs04" material="rs04_material"/>
        <geom type="mesh" class="collision" pos="0.05675 8.86335e-17 -0.07" quat="0.5 0.5 -0.5 -0.5" mesh="rs04" material="rs04_material"/>
        <!-- Link knee_driver -->
        <body name="knee_driver" pos="-0.03125 -3.55141e-15 -0.07" quat="0.00969587 0.70704 -0.00969587 -0.70704">
          <!-- Joint from hip to knee_driver -->
          <joint axis="0 0 1" name="knee" type="hinge"/>
          <inertial pos="0.00697592 -0.0183639 -0.0139906" mass="0.137736" fullinertia="9.84228e-05 4.23275e-05 0.00010894 2.49013e-05 8.46126e-06 -2.22518e-05"/>
          <!-- Part external_retaining_ring_na1_75__20720dc72ef1252dd7a3f008abb53421 -->
          <geom type="mesh" class="visual" pos="0.0186213 -0.0490385 -0.0461217" quat="1 -3.2375e-16 -2.16343e-16 1.23349e-15" mesh="external_retaining_ring_na1_75__20720dc72ef1252dd7a3f008abb53421" material="external_retaining_ring_na1_75__20720dc72ef1252dd7a3f008abb53421_material"/>
          <geom type="mesh" class="collision" pos="0.0186213 -0.0490385 -0.0461217" quat="1 -3.2375e-16 -2.16343e-16 1.23349e-15" mesh="external_retaining_ring_na1_75__20720dc72ef1252dd7a3f008abb53421" material="external_retaining_ring_na1_75__20720dc72ef1252dd7a3f008abb53421_material"/>
          <!-- Part knee_driver -->
          <geom type="mesh" class="visual" pos="-0.065 -0.2067 0.09925" quat="0.707107 0.707107 0 -1.22663e-18" mesh="knee_driver" material="knee_driver_material"/>
          <geom type="mesh" class="collision" pos="-0.065 -0.2067 0.09925" quat="0.707107 0.707107 0 -1.22663e-18" mesh="knee_driver" material="knee_driver_material"/>
          <!-- Part knee_driver_peg -->
          <geom type="mesh" class="visual" pos="-0.065 -0.2067 0.09925" quat="0.707107 0.707107 1.06424e-15 8.91436e-16" mesh="knee_driver_peg" material="knee_driver_peg_material"/>
          <geom type="mesh" class="collision" pos="-0.065 -0.2067 0.09925" quat="0.707107 0.707107 1.06424e-15 8.91436e-16" mesh="knee_driver_peg" material="knee_driver_peg_material"/>
          <!-- Frame closing_passive3_1 -->
          <site group="3" name="closing_passive3_1" pos="0.0186213 -0.0490385 -0.03125" quat="0 1 0 0"/>
          <!-- Frame closing_passive3_1_z -->
          <site group="3" name="closing_passive3_1_z" pos="0.0186213 -0.0490385 -0.13125" quat="0 1 0 0"/>
        </body>
        <!-- Link femur -->
        <body name="femur" pos="0.03125 -3.14202e-15 -0.07" quat="0.57661 0.409294 0.57661 0.409294">
          <!-- Joint from hip to femur -->
          <joint axis="0 0 1" name="hip-surge" type="hinge"/>
          <inertial pos="0.0181431 -0.142297 -0.0284693" mass="0.873721" fullinertia="0.00934167 0.000548911 0.00955404 0.00158406 3.77148e-05 -0.000341228"/>
          <!-- Part femur -->
          <geom type="mesh" class="visual" pos="-0.065 0.2067 -0.16175" quat="0.707107 -0.707107 -0 1.96262e-17" mesh="femur" material="femur_material"/>
          <geom type="mesh" class="collision" pos="-0.065 0.2067 -0.16175" quat="0.707107 -0.707107 -0 1.96262e-17" mesh="femur" material="femur_material"/>
          <!-- Link fibia -->
          <body name="fibia" pos="0.0533341 -0.329046 -0.03125" quat="0 1 0 0">
            <!-- Joint from femur to fibia -->
            <joint axis="0 0 1" name="passive1" type="hinge"/>
            <inertial pos="-0.213054 -0.0115817 0.000762104" mass="1.14788" fullinertia="0.000464178 0.0165692 0.0165507 -0.000879436 0.000111476 6.36586e-06"/>
            <!-- Part rs00 -->
            <geom type="mesh" class="visual" pos="-0.332861 -0.0180322 0.02375" quat="5.58095e-16 0.807436 0.589956 3.91837e-16" mesh="rs00" material="rs00_material"/>
            <geom type="mesh" class="collision" pos="-0.332861 -0.0180322 0.02375" quat="5.58095e-16 0.807436 0.589956 3.91837e-16" mesh="rs00" material="rs00_material"/>
            <!-- Part fibia -->
            <geom type="mesh" class="visual" pos="0.474444 -0.275553 0.1305" quat="0.570943 0.570943 0.417162 0.417162" mesh="fibia" material="fibia_material"/>
            <geom type="mesh" class="collision" pos="0.474444 -0.275553 0.1305" quat="0.570943 0.570943 0.417162 0.417162" mesh="fibia" material="fibia_material"/>
            <!-- Part tibia -->
            <geom type="mesh" class="visual" pos="0.474435 -0.275553 0.1305" quat="0.570943 0.570943 0.417162 0.417162" mesh="tibia" material="tibia_material"/>
            <geom type="mesh" class="collision" pos="0.474435 -0.275553 0.1305" quat="0.570943 0.570943 0.417162 0.417162" mesh="tibia" material="tibia_material"/>
            <!-- Link bearing_side -->
            <body name="bearing_side" pos="-0.332861 -0.0180322 0.02975" quat="4.0192e-16 0.977208 0.212286 1.71333e-17">
              <!-- Joint from fibia to bearing_side -->
              <joint axis="0 0 1" name="ankle" type="hinge"/>
              <inertial pos="-0.00890949 -0.0234629 0.0291104" mass="0.569274" fullinertia="0.000533464 0.00110059 0.000891801 0.000251637 3.34095e-06 8.7983e-06"/>
              <!-- Part motor_side -->
              <geom type="mesh" class="visual" pos="-6.93889e-16 0.847375 -0.10075" quat="0.707107 -0.707107 -0 1.96262e-17" mesh="motor_side" material="motor_side_material"/>
              <geom type="mesh" class="collision" pos="-6.93889e-16 0.847375 -0.10075" quat="0.707107 -0.707107 -0 1.96262e-17" mesh="motor_side" material="motor_side_material"/>
              <!-- Part foot_center -->
              <geom type="mesh" class="visual" pos="2.85882e-15 0.847375 -0.10075" quat="0.707107 -0.707107 4.82186e-16 -1.03567e-15" mesh="foot_center" material="foot_center_material"/>
              <geom type="mesh" class="collision" pos="2.85882e-15 0.847375 -0.10075" quat="0.707107 -0.707107 4.82186e-16 -1.03567e-15" mesh="foot_center" material="foot_center_material"/>
              <!-- Part bearing_side -->
              <geom type="mesh" class="visual" pos="-1.33227e-15 0.847375 -0.10075" quat="0.707107 -0.707107 1.57009e-16 -3.51099e-17" mesh="bearing_side" material="bearing_side_material"/>
              <geom type="mesh" class="collision" pos="-1.33227e-15 0.847375 -0.10075" quat="0.707107 -0.707107 1.57009e-16 -3.51099e-17" mesh="bearing_side" material="bearing_side_material"/>
            </body>
            <!-- Link align_bar -->
            <body name="align_bar" pos="0.0523782 0.0028375 -4.17477e-17" quat="0.807436 -4.64718e-16 -4.12805e-16 0.589956">
              <!-- Joint from fibia to align_bar -->
              <joint axis="0 0 1" name="passive2" type="hinge"/>
              <inertial pos="-0.17535 -0.0262293 6.12488e-10" mass="0.474343" fullinertia="0.00013979 0.00425782 0.00434396 -0.000623499 -3.58804e-11 -5.05709e-12"/>
              <!-- Part align_bar -->
              <geom type="mesh" class="visual" pos="-0.505308 -0.0174349 0.1305" quat="0.570943 0.570943 -0.417162 -0.417162" mesh="align_bar" material="align_bar_material"/>
              <geom type="mesh" class="collision" pos="-0.505308 -0.0174349 0.1305" quat="0.570943 0.570943 -0.417162 -0.417162" mesh="align_bar" material="align_bar_material"/>
              <!-- Frame closing_passive3_2 -->
              <site group="3" name="closing_passive3_2" pos="-0.329691 -0.049187 -1.30155e-16" quat="5.9401e-16 -0.988105 -0.153782 -1.81283e-16"/>
              <!-- Frame closing_passive3_2_z -->
              <site group="3" name="closing_passive3_2_z" pos="-0.329691 -0.049187 -0.1" quat="5.9401e-16 -0.988105 -0.153782 -1.81283e-16"/>
            </body>
          </body>
        </body>
      </body>
      <!-- Link hip_2 -->
      <body name="hip_2" pos="0.2 -0.0527 -2.05521e-15" quat="1.11022e-16 0 -0.707107 -0.707107">
        <!-- Joint from weight to hip_2 -->
        <joint axis="0 0 1" name="hip-sway (1)" type="hinge"/>
        <inertial pos="7.23173e-10 4.11021e-08 -0.0674747" mass="3.29742" fullinertia="0.00651198 0.0147053 0.0142296 7.75592e-05 -4.32513e-10 -6.63111e-09"/>
        <!-- Part hip_2 -->
        <geom type="mesh" class="visual" pos="-0.1305 0.2067 -0.005" quat="0.5 -0.5 0.5 0.5" mesh="hip" material="hip_material"/>
        <geom type="mesh" class="collision" pos="-0.1305 0.2067 -0.005" quat="0.5 -0.5 0.5 0.5" mesh="hip" material="hip_material"/>
        <!-- Part rs04_5 -->
        <geom type="mesh" class="visual" pos="-0.05675 9.54098e-17 -0.07" quat="0.5 0.5 0.5 0.5" mesh="rs04" material="rs04_material"/>
        <geom type="mesh" class="collision" pos="-0.05675 9.54098e-17 -0.07" quat="0.5 0.5 0.5 0.5" mesh="rs04" material="rs04_material"/>
        <!-- Part rs04_6 -->
        <geom type="mesh" class="visual" pos="0.05675 1.06685e-16 -0.07" quat="0.5 0.5 -0.5 -0.5" mesh="rs04" material="rs04_material"/>
        <geom type="mesh" class="collision" pos="0.05675 1.06685e-16 -0.07" quat="0.5 0.5 -0.5 -0.5" mesh="rs04" material="rs04_material"/>
        <!-- Link knee_driver_2 -->
        <body name="knee_driver_2" pos="-0.03125 -1.30321e-15 -0.07" quat="0.0153957 0.706939 -0.0153957 -0.706939">
          <!-- Joint from hip_2 to knee_driver_2 -->
          <joint axis="0 0 1" name="knee (1)" type="hinge"/>
          <inertial pos="0.00689243 -0.018151 -0.0137602" mass="0.136755" fullinertia="9.64797e-05 4.11284e-05 0.000107837 2.45597e-05 8.09176e-06 -2.13094e-05"/>
          <!-- Part knee_driver_peg_2 -->
          <geom type="mesh" class="visual" pos="-0.065 -0.2067 0.09925" quat="0.707107 0.707107 1.06424e-15 9.65034e-16" mesh="knee_driver_peg" material="knee_driver_peg_material"/>
          <geom type="mesh" class="collision" pos="-0.065 -0.2067 0.09925" quat="0.707107 0.707107 1.06424e-15 9.65034e-16" mesh="knee_driver_peg" material="knee_driver_peg_material"/>
          <!-- Part knee_driver_2 -->
          <geom type="mesh" class="visual" pos="-0.065 -0.2067 0.09925" quat="0.707107 0.707107 -0 2.45327e-18" mesh="knee_driver" material="knee_driver_material"/>
          <geom type="mesh" class="collision" pos="-0.065 -0.2067 0.09925" quat="0.707107 0.707107 -0 2.45327e-18" mesh="knee_driver" material="knee_driver_material"/>
          <!-- Frame closing_passive3 (1)_1 -->
          <site group="3" name="closing_passive3 (1)_1" pos="0.0186213 -0.0490385 -0.03125" quat="0 1 0 0"/>
          <!-- Frame closing_passive3 (1)_1_z -->
          <site group="3" name="closing_passive3 (1)_1_z" pos="0.0186213 -0.0490385 -0.13125" quat="0 1 0 0"/>
        </body>
        <!-- Link femur_2 -->
        <body name="femur_2" pos="0.03125 -3.1212e-15 -0.07" quat="0.545716 0.449659 0.545716 0.449659">
          <!-- Joint from hip_2 to femur_2 -->
          <joint axis="0 0 1" name="hip-surge (1)" type="hinge"/>
          <inertial pos="0.0181431 -0.142297 -0.0284693" mass="0.873721" fullinertia="0.00934167 0.000548911 0.00955404 0.00158406 3.77148e-05 -0.000341228"/>
          <!-- Part femur_2 -->
          <geom type="mesh" class="visual" pos="-0.065 0.2067 -0.16175" quat="0.707107 -0.707107 0 0" mesh="femur" material="femur_material"/>
          <geom type="mesh" class="collision" pos="-0.065 0.2067 -0.16175" quat="0.707107 -0.707107 0 0" mesh="femur" material="femur_material"/>
          <!-- Link fibia_2 -->
          <body name="fibia_2" pos="0.0533341 -0.329046 -0.03125" quat="0 1 0 0">
            <!-- Joint from femur_2 to fibia_2 -->
            <joint axis="0 0 1" name="passive1 (1)" type="hinge"/>
            <inertial pos="-0.20849 -0.0453619 0.000762104" mass="1.14788" fullinertia="0.00114911 0.0158843 0.0165507 -0.00336678 0.00010904 2.40368e-05"/>
            <!-- Part fibia_2 -->
            <geom type="mesh" class="visual" pos="0.51227 -0.196483 0.1305" quat="0.535797 0.535797 0.461435 0.461435" mesh="fibia" material="fibia_material"/>
            <geom type="mesh" class="collision" pos="0.51227 -0.196483 0.1305" quat="0.535797 0.535797 0.461435 0.461435" mesh="fibia" material="fibia_material"/>
            <!-- Part tibia_2 -->
            <geom type="mesh" class="visual" pos="0.512262 -0.196485 0.1305" quat="0.535797 0.535797 0.461435 0.461435" mesh="tibia" material="tibia_material"/>
            <geom type="mesh" class="collision" pos="0.512262 -0.196485 0.1305" quat="0.535797 0.535797 0.461435 0.461435" mesh="tibia" material="tibia_material"/>
            <!-- Part rs00_2 -->
            <geom type="mesh" class="visual" pos="-0.325741 -0.0708089 0.02375" quat="1.10917e-15 -0.757731 -0.652567 7.94473e-17" mesh="rs00" material="rs00_material"/>
            <geom type="mesh" class="collision" pos="-0.325741 -0.0708089 0.02375" quat="1.10917e-15 -0.757731 -0.652567 7.94473e-17" mesh="rs00" material="rs00_material"/>
            <!-- Link bearing_side_2 -->
            <body name="bearing_side_2" pos="-0.325741 -0.0708089 0.02975" quat="7.24566e-16 -0.944817 -0.327598 4.06128e-17">
              <!-- Joint from fibia_2 to bearing_side_2 -->
              <joint axis="0 0 1" name="ankle (1)" type="hinge"/>
              <inertial pos="-0.00890949 -0.0234629 0.0291104" mass="0.569274" fullinertia="0.000533464 0.00110059 0.000891801 0.000251637 3.34095e-06 8.7983e-06"/>
              <!-- Part foot_center_2 -->
              <geom type="mesh" class="visual" pos="3.16414e-15 0.847375 -0.10075" quat="0.707107 -0.707107 4.17151e-16 -1.02585e-15" mesh="foot_center" material="foot_center_material"/>
              <geom type="mesh" class="collision" pos="3.16414e-15 0.847375 -0.10075" quat="0.707107 -0.707107 4.17151e-16 -1.02585e-15" mesh="foot_center" material="foot_center_material"/>
              <!-- Part bearing_side_2 -->
              <geom type="mesh" class="visual" pos="-8.32667e-16 0.847375 -0.10075" quat="0.707107 -0.707107 -0 -5.67063e-18" mesh="bearing_side" material="bearing_side_material"/>
              <geom type="mesh" class="collision" pos="-8.32667e-16 0.847375 -0.10075" quat="0.707107 -0.707107 -0 -5.67063e-18" mesh="bearing_side" material="bearing_side_material"/>
              <!-- Part motor_side_2 -->
              <geom type="mesh" class="visual" pos="-7.49401e-16 0.847375 -0.10075" quat="0.707107 -0.707107 0 1.96262e-17" mesh="motor_side" material="motor_side_material"/>
              <geom type="mesh" class="collision" pos="-7.49401e-16 0.847375 -0.10075" quat="0.707107 -0.707107 0 1.96262e-17" mesh="motor_side" material="motor_side_material"/>
            </body>
            <!-- Link align_bar_2 -->
            <body name="align_bar_2" pos="0.0512579 0.0111423 -1.97065e-15" quat="0.757731 -0 2.22045e-16 0.652567">
              <!-- Joint from fibia_2 to align_bar_2 -->
              <joint axis="0 0 1" name="passive2 (1)" type="hinge"/>
              <inertial pos="-0.177289 0.00202921 6.12487e-10" mass="0.474343" fullinertia="4.81747e-05 0.00434943 0.00434396 5.55363e-05 -3.62279e-11 7.2127e-13"/>
              <!-- Part align_bar_2 -->
              <geom type="mesh" class="visual" pos="-0.501637 0.0632561 0.1305" quat="0.535797 0.535797 -0.461435 -0.461435" mesh="align_bar" material="align_bar_material"/>
              <geom type="mesh" class="collision" pos="-0.501637 0.0632561 0.1305" quat="0.535797 0.535797 -0.461435 -0.461435" mesh="align_bar" material="align_bar_material"/>
              <!-- Frame closing_passive3 (1)_2 -->
              <site group="3" name="closing_passive3 (1)_2" pos="-0.333317 0.00394278 -7.21645e-16" quat="1.15933e-16 -0.997231 -0.074362 -3.78944e-17"/>
              <!-- Frame closing_passive3 (1)_2_z -->
              <site group="3" name="closing_passive3 (1)_2_z" pos="-0.333317 0.00394278 -0.1" quat="1.15933e-16 -0.997231 -0.074362 -3.78944e-17"/>
            </body>
          </body>
        </body>
      </body>
    </body>
  </worldbody>
  <asset>
    <mesh file="hip.stl"/>
    <mesh file="knee_driver_peg.stl"/>
    <mesh file="rs00.stl"/>
    <mesh file="knee_driver.stl"/>
    <mesh file="bearing_side.stl"/>
    <mesh file="femur.stl"/>
    <mesh file="rs04.stl"/>
    <mesh file="fibia.stl"/>
    <mesh file="foot_center.stl"/>
    <mesh file="motor_side.stl"/>
    <mesh file="weight.stl"/>
    <mesh file="external_retaining_ring_na1_75__20720dc72ef1252dd7a3f008abb53421.stl"/>
    <mesh file="align_bar.stl"/>
    <mesh file="tibia.stl"/>
    <material name="rs04_material" rgba="0.615686 0.811765 0.929412 1"/>
    <material name="weight_material" rgba="1 0 0 1"/>
    <material name="hip_material" rgba="0.301961 0.301961 0.301961 1"/>
    <material name="external_retaining_ring_na1_75__20720dc72ef1252dd7a3f008abb53421_material" rgba="0.603922 0.647059 0.686275 1"/>
    <material name="knee_driver_material" rgba="0.972549 0.529412 0.00392157 1"/>
    <material name="knee_driver_peg_material" rgba="0.498039 0.498039 0.498039 1"/>
    <material name="femur_material" rgba="0.647059 0.647059 0.647059 1"/>
    <material name="rs00_material" rgba="0.647059 0.647059 0.647059 1"/>
    <material name="fibia_material" rgba="0.917647 0.917647 0.917647 1"/>
    <material name="tibia_material" rgba="0.917647 0.917647 0.917647 1"/>
    <material name="motor_side_material" rgba="0.301961 0.301961 0.301961 1"/>
    <material name="foot_center_material" rgba="0.301961 0.301961 0.301961 1"/>
    <material name="bearing_side_material" rgba="0.301961 0.301961 0.301961 1"/>
    <material name="align_bar_material" rgba="0.231373 0.380392 0.705882 1"/>
  </asset>
  <sensor>
    <accelerometer name="imu_accel" site="imu_weight"/>
    <gyro name="imu_gyro" site="imu_weight"/>
    <actuatorfrc name="hip_sway_torque" actuator="hip-sway"/>
    <actuatorfrc name="knee_torque" actuator="knee"/>
    <actuatorfrc name="hip_surge_torque" actuator="hip-surge"/>
    <actuatorfrc name="ankle_torque" actuator="ankle"/>
    <actuatorfrc name="hip_sway_2_torque" actuator="hip-sway (1)"/>
    <actuatorfrc name="knee_2_torque" actuator="knee (1)"/>
    <actuatorfrc name="hip_surge_2_torque" actuator="hip-surge (1)"/>
    <actuatorfrc name="ankle_2_torque" actuator="ankle (1)"/>
  </sensor>
  <actuator>
    <motor class="leg" name="hip-sway" joint="hip-sway"/>
    <motor class="leg" name="knee" joint="knee"/>
    <motor class="leg" name="hip-surge" joint="hip-surge"/>
    <motor class="leg" name="ankle" joint="ankle"/>
    <motor class="leg" name="hip-sway (1)" joint="hip-sway (1)"/>
    <motor class="leg" name="knee (1)" joint="knee (1)"/>
    <motor class="leg" name="hip-surge (1)" joint="hip-surge (1)"/>
    <motor class="leg" name="ankle (1)" joint="ankle (1)"/>
  </actuator>
  <equality>
    <connect site1="closing_passive3_1" site2="closing_passive3_2"/>
    <connect site1="closing_passive3_1_z" site2="closing_passive3_2_z"/>
    <connect site1="closing_passive3 (1)_1" site2="closing_passive3 (1)_2"/>
    <connect site1="closing_passive3 (1)_1_z" site2="closing_passive3 (1)_2_z"/>
  </equality>
</mujoco>
